Workbook
Name CustNames: 'Customer Database'!$A$2:$A$501
Name EmpNames: Employee!$A$2:$A$21
Name ProductNames: Inventory!$A$2:$A$201
Name ServiceKeys: Services!$D$2:$D$120

Sheet Dashboard
A1: PRISM BEAUTY — Dashboard
A2: Updates automatically as you log sales, purchases and expenses. Set your start month in B4.
A4: P&L start month | B4: =EOMONTH(TODAY(),-11)+1 -> 45870 | C4: ← type your parlor's start month (e.g. 01-09-2025)
A6: KEY NUMBERS | H6: SERVICE CATEGORY PERFORMANCE
A7: Revenue (this month) | B7: =SUMIFS('Daily tracking'!$G$2:$G$2001,'Daily tracking'!$A$2:$A$2001,">="&EOMONTH(TODAY(),-1)+1,'Daily tracking'!$A$2:$A$2001,"<="&EOMONTH(TODAY(),0)) -> 0 | H7: Category | I7: Revenue | J7: Bookings
A8: Revenue (all time) | B8: =SUM('Daily tracking'!$G$2:$G$2001) -> 0 | H8: Threading | I8: =SUMIF('Daily tracking'!$H$2:$H$2001,H8,'Daily tracking'!$G$2:$G$2001) -> 0 | J8: =COUNTIF('Daily tracking'!$H$2:$H$2001,H8) -> 0
A9: Monthly salary cost | B9: =SUM(Employee!$B$2:$B$21) -> 48000 | H9: Waxing | I9: =SUMIF('Daily tracking'!$H$2:$H$2001,H9,'Daily tracking'!$G$2:$G$2001) -> 0 | J9: =COUNTIF('Daily tracking'!$H$2:$H$2001,H9) -> 0
A10: Product purchases (this month) | B10: =SUMIFS(Purchases!$E$2:$E$1001,Purchases!$A$2:$A$1001,">="&EOMONTH(TODAY(),-1)+1,Purchases!$A$2:$A$1001,"<="&EOMONTH(TODAY(),0)) -> 0 | H10: Roll on - Wax | I10: =SUMIF('Daily tracking'!$H$2:$H$2001,H10,'Daily tracking'!$G$2:$G$2001) -> 0 | J10: =COUNTIF('Daily tracking'!$H$2:$H$2001,H10) -> 0
A11: Other expenses (this month) | B11: =SUMIFS(Expenses!$C$2:$C$501,Expenses!$A$2:$A$501,">="&EOMONTH(TODAY(),-1)+1,Expenses!$A$2:$A$501,"<="&EOMONTH(TODAY(),0)) -> 0 | H11: Lipo - Wax | I11: =SUMIF('Daily tracking'!$H$2:$H$2001,H11,'Daily tracking'!$G$2:$G$2001) -> 0 | J11: =COUNTIF('Daily tracking'!$H$2:$H$2001,H11) -> 0
A12: Profit (this month) | B12: =B7-B9-B10-B11 -> -48000 | H12: Spa | I12: =SUMIF('Daily tracking'!$H$2:$H$2001,H12,'Daily tracking'!$G$2:$G$2001) -> 0 | J12: =COUNTIF('Daily tracking'!$H$2:$H$2001,H12) -> 0
A13: Stock value on hand | B13: =SUM(Inventory!$L$2:$L$201) -> 0 | H13: Pedicure | I13: =SUMIF('Daily tracking'!$H$2:$H$2001,H13,'Daily tracking'!$G$2:$G$2001) -> 0 | J13: =COUNTIF('Daily tracking'!$H$2:$H$2001,H13) -> 0
A14: Items to reorder | B14: =COUNTIF(Inventory!$J$2:$J$201,"REORDER") -> 0 | H14: Manicure | I14: =SUMIF('Daily tracking'!$H$2:$H$2001,H14,'Daily tracking'!$G$2:$G$2001) -> 0 | J14: =COUNTIF('Daily tracking'!$H$2:$H$2001,H14) -> 0
A15: Active customers | B15: =COUNTIF('Customer Database'!$G$2:$G$501,"Active")+COUNTIF('Customer Database'!$G$2:$G$501,"Loyal") -> 0 | H15: Combo - meni & pedi | I15: =SUMIF('Daily tracking'!$H$2:$H$2001,H15,'Daily tracking'!$G$2:$G$2001) -> 0 | J15: =COUNTIF('Daily tracking'!$H$2:$H$2001,H15) -> 0
A16: At-risk (message them!) | B16: =COUNTIF('Customer Database'!$G$2:$G$501,"At risk") -> 0 | H16: Nail extension | I16: =SUMIF('Daily tracking'!$H$2:$H$2001,H16,'Daily tracking'!$G$2:$G$2001) -> 0 | J16: =COUNTIF('Daily tracking'!$H$2:$H$2001,H16) -> 0
A17: Lapsed customers | B17: =COUNTIF('Customer Database'!$G$2:$G$501,"Lapsed") -> 0 | H17: Nail polish | I17: =SUMIF('Daily tracking'!$H$2:$H$2001,H17,'Daily tracking'!$G$2:$G$2001) -> 0 | J17: =COUNTIF('Daily tracking'!$H$2:$H$2001,H17) -> 0
A18: Loyal customers | B18: =COUNTIF('Customer Database'!$G$2:$G$501,"Loyal") -> 0 | H18: Hair | I18: =SUMIF('Daily tracking'!$H$2:$H$2001,H18,'Daily tracking'!$G$2:$G$2001) -> 0 | J18: =COUNTIF('Daily tracking'!$H$2:$H$2001,H18) -> 0
A19: Repeat rate | B19: =IFERROR(COUNTIF('Customer Database'!$C$2:$C$501,">1")/COUNTIF('Customer Database'!$C$2:$C$501,">0"),0) -> 0 | H19: Hair treatment | I19: =SUMIF('Daily tracking'!$H$2:$H$2001,H19,'Daily tracking'!$G$2:$G$2001) -> 0 | J19: =COUNTIF('Daily tracking'!$H$2:$H$2001,H19) -> 0
H20: Hair color | I20: =SUMIF('Daily tracking'!$H$2:$H$2001,H20,'Daily tracking'!$G$2:$G$2001) -> 0 | J20: =COUNTIF('Daily tracking'!$H$2:$H$2001,H20) -> 0
A21: MONTHLY P&L | H21: Facial | I21: =SUMIF('Daily tracking'!$H$2:$H$2001,H21,'Daily tracking'!$G$2:$G$2001) -> 0 | J21: =COUNTIF('Daily tracking'!$H$2:$H$2001,H21) -> 0
A22: Month | B22: Revenue | C22: Salaries | D22: Products | E22: Other Exp. | F22: Profit | G22: Margin
A23: =$B$4 -> 45870 | B23: =SUMIFS('Daily tracking'!$G$2:$G$2001,'Daily tracking'!$A$2:$A$2001,">="&A23,'Daily tracking'!$A$2:$A$2001,"<="&EOMONTH(A23,0)) -> 0 | C23: =$B$9 -> 48000 | D23: =SUMIFS(Purchases!$E$2:$E$1001,Purchases!$A$2:$A$1001,">="&A23,Purchases!$A$2:$A$1001,"<="&EOMONTH(A23,0)) -> 0 | E23: =SUMIFS(Expenses!$C$2:$C$501,Expenses!$A$2:$A$501,">="&A23,Expenses!$A$2:$A$501,"<="&EOMONTH(A23,0)) -> 0 | F23: =B23-C23-D23-E23 -> -48000 | G23: =IF(B23=0,"",F23/B23)
A24: =EOMONTH(A23,0)+1 -> 45901 | B24: =SUMIFS('Daily tracking'!$G$2:$G$2001,'Daily tracking'!$A$2:$A$2001,">="&A24,'Daily tracking'!$A$2:$A$2001,"<="&EOMONTH(A24,0)) -> 0 | C24: =$B$9 -> 48000 | D24: =SUMIFS(Purchases!$E$2:$E$1001,Purchases!$A$2:$A$1001,">="&A24,Purchases!$A$2:$A$1001,"<="&EOMONTH(A24,0)) -> 0 | E24: =SUMIFS(Expenses!$C$2:$C$501,Expenses!$A$2:$A$501,">="&A24,Expenses!$A$2:$A$501,"<="&EOMONTH(A24,0)) -> 0 | F24: =B24-C24-D24-E24 -> -48000 | G24: =IF(B24=0,"",F24/B24) | H24: EMPLOYEE PERFORMANCE
A25: =EOMONTH(A24,0)+1 -> 45931 | B25: =SUMIFS('Daily tracking'!$G$2:$G$2001,'Daily tracking'!$A$2:$A$2001,">="&A25,'Daily tracking'!$A$2:$A$2001,"<="&EOMONTH(A25,0)) -> 0 | C25: =$B$9 -> 48000 | D25: =SUMIFS(Purchases!$E$2:$E$1001,Purchases!$A$2:$A$1001,">="&A25,Purchases!$A$2:$A$1001,"<="&EOMONTH(A25,0)) -> 0 | E25: =SUMIFS(Expenses!$C$2:$C$501,Expenses!$A$2:$A$501,">="&A25,Expenses!$A$2:$A$501,"<="&EOMONTH(A25,0)) -> 0 | F25: =B25-C25-D25-E25 -> -48000 | G25: =IF(B25=0,"",F25/B25) | H25: Employee | I25: Revenue | J25: Services
A26: =EOMONTH(A25,0)+1 -> 45962 | B26: =SUMIFS('Daily tracking'!$G$2:$G$2001,'Daily tracking'!$A$2:$A$2001,">="&A26,'Daily tracking'!$A$2:$A$2001,"<="&EOMONTH(A26,0)) -> 0 | C26: =$B$9 -> 48000 | D26: =SUMIFS(Purchases!$E$2:$E$1001,Purchases!$A$2:$A$1001,">="&A26,Purchases!$A$2:$A$1001,"<="&EOMONTH(A26,0)) -> 0 | E26: =SUMIFS(Expenses!$C$2:$C$501,Expenses!$A$2:$A$501,">="&A26,Expenses!$A$2:$A$501,"<="&EOMONTH(A26,0)) -> 0 | F26: =B26-C26-D26-E26 -> -48000 | G26: =IF(B26=0,"",F26/B26) | H26: =IF(Employee!A2="","",Employee!A2) -> Rachna | I26: =IF(Employee!A2="","",Employee!D2) -> 0 | J26: =IF(Employee!A2="","",Employee!C2) -> 0
A27: =EOMONTH(A26,0)+1 -> 45992 | B27: =SUMIFS('Daily tracking'!$G$2:$G$2001,'Daily tracking'!$A$2:$A$2001,">="&A27,'Daily tracking'!$A$2:$A$2001,"<="&EOMONTH(A27,0)) -> 0 | C27: =$B$9 -> 48000 | D27: =SUMIFS(Purchases!$E$2:$E$1001,Purchases!$A$2:$A$1001,">="&A27,Purchases!$A$2:$A$1001,"<="&EOMONTH(A27,0)) -> 0 | E27: =SUMIFS(Expenses!$C$2:$C$501,Expenses!$A$2:$A$501,">="&A27,Expenses!$A$2:$A$501,"<="&EOMONTH(A27,0)) -> 0 | F27: =B27-C27-D27-E27 -> -48000 | G27: =IF(B27=0,"",F27/B27) | H27: =IF(Employee!A3="","",Employee!A3) -> Feroz | I27: =IF(Employee!A3="","",Employee!D3) -> 0 | J27: =IF(Employee!A3="","",Employee!C3) -> 0
A28: =EOMONTH(A27,0)+1 -> 46023 | B28: =SUMIFS('Daily tracking'!$G$2:$G$2001,'Daily tracking'!$A$2:$A$2001,">="&A28,'Daily tracking'!$A$2:$A$2001,"<="&EOMONTH(A28,0)) -> 0 | C28: =$B$9 -> 48000 | D28: =SUMIFS(Purchases!$E$2:$E$1001,Purchases!$A$2:$A$1001,">="&A28,Purchases!$A$2:$A$1001,"<="&EOMONTH(A28,0)) -> 0 | E28: =SUMIFS(Expenses!$C$2:$C$501,Expenses!$A$2:$A$501,">="&A28,Expenses!$A$2:$A$501,"<="&EOMONTH(A28,0)) -> 0 | F28: =B28-C28-D28-E28 -> -48000 | G28: =IF(B28=0,"",F28/B28) | H28: =IF(Employee!A4="","",Employee!A4) -> Mona | I28: =IF(Employee!A4="","",Employee!D4) -> 0 | J28: =IF(Employee!A4="","",Employee!C4) -> 0
A29: =EOMONTH(A28,0)+1 -> 46054 | B29: =SUMIFS('Daily tracking'!$G$2:$G$2001,'Daily tracking'!$A$2:$A$2001,">="&A29,'Daily tracking'!$A$2:$A$2001,"<="&EOMONTH(A29,0)) -> 0 | C29: =$B$9 -> 48000 | D29: =SUMIFS(Purchases!$E$2:$E$1001,Purchases!$A$2:$A$1001,">="&A29,Purchases!$A$2:$A$1001,"<="&EOMONTH(A29,0)) -> 0 | E29: =SUMIFS(Expenses!$C$2:$C$501,Expenses!$A$2:$A$501,">="&A29,Expenses!$A$2:$A$501,"<="&EOMONTH(A29,0)) -> 0 | F29: =B29-C29-D29-E29 -> -48000 | G29: =IF(B29=0,"",F29/B29) | H29: =IF(Employee!A5="","",Employee!A5) -> Chandni | I29: =IF(Employee!A5="","",Employee!D5) -> 0 | J29: =IF(Employee!A5="","",Employee!C5) -> 0
A30: =EOMONTH(A29,0)+1 -> 46082 | B30: =SUMIFS('Daily tracking'!$G$2:$G$2001,'Daily tracking'!$A$2:$A$2001,">="&A30,'Daily tracking'!$A$2:$A$2001,"<="&EOMONTH(A30,0)) -> 0 | C30: =$B$9 -> 48000 | D30: =SUMIFS(Purchases!$E$2:$E$1001,Purchases!$A$2:$A$1001,">="&A30,Purchases!$A$2:$A$1001,"<="&EOMONTH(A30,0)) -> 0 | E30: =SUMIFS(Expenses!$C$2:$C$501,Expenses!$A$2:$A$501,">="&A30,Expenses!$A$2:$A$501,"<="&EOMONTH(A30,0)) -> 0 | F30: =B30-C30-D30-E30 -> -48000 | G30: =IF(B30=0,"",F30/B30) | H30: =IF(Employee!A6="","",Employee!A6) | I30: =IF(Employee!A6="","",Employee!D6) | J30: =IF(Employee!A6="","",Employee!C6)
A31: =EOMONTH(A30,0)+1 -> 46113 | B31: =SUMIFS('Daily tracking'!$G$2:$G$2001,'Daily tracking'!$A$2:$A$2001,">="&A31,'Daily tracking'!$A$2:$A$2001,"<="&EOMONTH(A31,0)) -> 0 | C31: =$B$9 -> 48000 | D31: =SUMIFS(Purchases!$E$2:$E$1001,Purchases!$A$2:$A$1001,">="&A31,Purchases!$A$2:$A$1001,"<="&EOMONTH(A31,0)) -> 0 | E31: =SUMIFS(Expenses!$C$2:$C$501,Expenses!$A$2:$A$501,">="&A31,Expenses!$A$2:$A$501,"<="&EOMONTH(A31,0)) -> 0 | F31: =B31-C31-D31-E31 -> -48000 | G31: =IF(B31=0,"",F31/B31) | H31: =IF(Employee!A7="","",Employee!A7) | I31: =IF(Employee!A7="","",Employee!D7) | J31: =IF(Employee!A7="","",Employee!C7)
A32: =EOMONTH(A31,0)+1 -> 46143 | B32: =SUMIFS('Daily tracking'!$G$2:$G$2001,'Daily tracking'!$A$2:$A$2001,">="&A32,'Daily tracking'!$A$2:$A$2001,"<="&EOMONTH(A32,0)) -> 0 | C32: =$B$9 -> 48000 | D32: =SUMIFS(Purchases!$E$2:$E$1001,Purchases!$A$2:$A$1001,">="&A32,Purchases!$A$2:$A$1001,"<="&EOMONTH(A32,0)) -> 0 | E32: =SUMIFS(Expenses!$C$2:$C$501,Expenses!$A$2:$A$501,">="&A32,Expenses!$A$2:$A$501,"<="&EOMONTH(A32,0)) -> 0 | F32: =B32-C32-D32-E32 -> -48000 | G32: =IF(B32=0,"",F32/B32) | H32: =IF(Employee!A8="","",Employee!A8) | I32: =IF(Employee!A8="","",Employee!D8) | J32: =IF(Employee!A8="","",Employee!C8)
A33: =EOMONTH(A32,0)+1 -> 46174 | B33: =SUMIFS('Daily tracking'!$G$2:$G$2001,'Daily tracking'!$A$2:$A$2001,">="&A33,'Daily tracking'!$A$2:$A$2001,"<="&EOMONTH(A33,0)) -> 0 | C33: =$B$9 -> 48000 | D33: =SUMIFS(Purchases!$E$2:$E$1001,Purchases!$A$2:$A$1001,">="&A33,Purchases!$A$2:$A$1001,"<="&EOMONTH(A33,0)) -> 0 | E33: =SUMIFS(Expenses!$C$2:$C$501,Expenses!$A$2:$A$501,">="&A33,Expenses!$A$2:$A$501,"<="&EOMONTH(A33,0)) -> 0 | F33: =B33-C33-D33-E33 -> -48000 | G33: =IF(B33=0,"",F33/B33) | H33: =IF(Employee!A9="","",Employee!A9) | I33: =IF(Employee!A9="","",Employee!D9) | J33: =IF(Employee!A9="","",Employee!C9)
A34: =EOMONTH(A33,0)+1 -> 46204 | B34: =SUMIFS('Daily tracking'!$G$2:$G$2001,'Daily tracking'!$A$2:$A$2001,">="&A34,'Daily tracking'!$A$2:$A$2001,"<="&EOMONTH(A34,0)) -> 0 | C34: =$B$9 -> 48000 | D34: =SUMIFS(Purchases!$E$2:$E$1001,Purchases!$A$2:$A$1001,">="&A34,Purchases!$A$2:$A$1001,"<="&EOMONTH(A34,0)) -> 0 | E34: =SUMIFS(Expenses!$C$2:$C$501,Expenses!$A$2:$A$501,">="&A34,Expenses!$A$2:$A$501,"<="&EOMONTH(A34,0)) -> 0 | F34: =B34-C34-D34-E34 -> -48000 | G34: =IF(B34=0,"",F34/B34) | H34: =IF(Employee!A10="","",Employee!A10) | I34: =IF(Employee!A10="","",Employee!D10) | J34: =IF(Employee!A10="","",Employee!C10)
A35: =EOMONTH(A34,0)+1 -> 46235 | B35: =SUMIFS('Daily tracking'!$G$2:$G$2001,'Daily tracking'!$A$2:$A$2001,">="&A35,'Daily tracking'!$A$2:$A$2001,"<="&EOMONTH(A35,0)) -> 0 | C35: =$B$9 -> 48000 | D35: =SUMIFS(Purchases!$E$2:$E$1001,Purchases!$A$2:$A$1001,">="&A35,Purchases!$A$2:$A$1001,"<="&EOMONTH(A35,0)) -> 0 | E35: =SUMIFS(Expenses!$C$2:$C$501,Expenses!$A$2:$A$501,">="&A35,Expenses!$A$2:$A$501,"<="&EOMONTH(A35,0)) -> 0 | F35: =B35-C35-D35-E35 -> -48000 | G35: =IF(B35=0,"",F35/B35) | H35: =IF(Employee!A11="","",Employee!A11) | I35: =IF(Employee!A11="","",Employee!D11) | J35: =IF(Employee!A11="","",Employee!C11)
A36: =EOMONTH(A35,0)+1 -> 46266 | B36: =SUMIFS('Daily tracking'!$G$2:$G$2001,'Daily tracking'!$A$2:$A$2001,">="&A36,'Daily tracking'!$A$2:$A$2001,"<="&EOMONTH(A36,0)) -> 0 | C36: =$B$9 -> 48000 | D36: =SUMIFS(Purchases!$E$2:$E$1001,Purchases!$A$2:$A$1001,">="&A36,Purchases!$A$2:$A$1001,"<="&EOMONTH(A36,0)) -> 0 | E36: =SUMIFS(Expenses!$C$2:$C$501,Expenses!$A$2:$A$501,">="&A36,Expenses!$A$2:$A$501,"<="&EOMONTH(A36,0)) -> 0 | F36: =B36-C36-D36-E36 -> -48000 | G36: =IF(B36=0,"",F36/B36) | H36: =IF(Employee!A12="","",Employee!A12) | I36: =IF(Employee!A12="","",Employee!D12) | J36: =IF(Employee!A12="","",Employee!C12)
A37: =EOMONTH(A36,0)+1 -> 46296 | B37: =SUMIFS('Daily tracking'!$G$2:$G$2001,'Daily tracking'!$A$2:$A$2001,">="&A37,'Daily tracking'!$A$2:$A$2001,"<="&EOMONTH(A37,0)) -> 0 | C37: =$B$9 -> 48000 | D37: =SUMIFS(Purchases!$E$2:$E$1001,Purchases!$A$2:$A$1001,">="&A37,Purchases!$A$2:$A$1001,"<="&EOMONTH(A37,0)) -> 0 | E37: =SUMIFS(Expenses!$C$2:$C$501,Expenses!$A$2:$A$501,">="&A37,Expenses!$A$2:$A$501,"<="&EOMONTH(A37,0)) -> 0 | F37: =B37-C37-D37-E37 -> -48000 | G37: =IF(B37=0,"",F37/B37) | H37: =IF(Employee!A13="","",Employee!A13) | I37: =IF(Employee!A13="","",Employee!D13) | J37: =IF(Employee!A13="","",Employee!C13)
... A40: =EOMONTH(A39,0)+1 -> 46388 | B40: =SUMIFS('Daily tracking'!$G$2:$G$2001,'Daily tracking'!$A$2:$A$2001,">="&A40,'Daily tracking'!$A$2:$A$2001,"<="&EOMONTH(A40,0)) -> 0 | C40: =$B$9 -> 48000 | D40: =SUMIFS(Purchases!$E$2:$E$1001,Purchases!$A$2:$A$1001,">="&A40,Purchases!$A$2:$A$1001,"<="&EOMONTH(A40,0)) -> 0 | E40: =SUMIFS(Expenses!$C$2:$C$501,Expenses!$A$2:$A$501,">="&A40,Expenses!$A$2:$A$501,"<="&EOMONTH(A40,0)) -> 0 | F40: =B40-C40-D40-E40 -> -48000 | G40: =IF(B40=0,"",F40/B40) | H40: =IF(Employee!A16="","",Employee!A16) | I40: =IF(Employee!A16="","",Employee!D16) | J40: =IF(Employee!A16="","",Employee!C16)
H41: =IF(Employee!A17="","",Employee!A17) | I41: =IF(Employee!A17="","",Employee!D17) | J41: =IF(Employee!A17="","",Employee!C17)
A42: REVENUE MIX & PAYMENTS (this month) | D42: CUSTOMER VALUE | H42: =IF(Employee!A18="","",Employee!A18) | I42: =IF(Employee!A18="","",Employee!D18) | J42: =IF(Employee!A18="","",Employee!C18)
A43: Service revenue | B43: =SUMIFS('Daily tracking'!$G$2:$G$2001,'Daily tracking'!$J$2:$J$2001,"Service",'Daily tracking'!$A$2:$A$2001,">="&EOMONTH(TODAY(),-1)+1,'Daily tracking'!$A$2:$A$2001,"<="&EOMONTH(TODAY(),0)) -> 0 | D43: VIP customers | E43: =COUNTIF('Customer Database'!$O$2:$O$501,"VIP") -> 0 | H43: =IF(Employee!A19="","",Employee!A19) | I43: =IF(Employee!A19="","",Employee!D19) | J43: =IF(Employee!A19="","",Employee!C19)
A44: Retail revenue | B44: =SUMIFS('Daily tracking'!$G$2:$G$2001,'Daily tracking'!$J$2:$J$2001,"Retail",'Daily tracking'!$A$2:$A$2001,">="&EOMONTH(TODAY(),-1)+1,'Daily tracking'!$A$2:$A$2001,"<="&EOMONTH(TODAY(),0)) -> 0 | D44: High-value customers | E44: =COUNTIF('Customer Database'!$O$2:$O$501,"High value") -> 0 | H44: =IF(Employee!A20="","",Employee!A20) | I44: =IF(Employee!A20="","",Employee!D20) | J44: =IF(Employee!A20="","",Employee!C20)
...

Sheet Daily tracking
A1: Date | B1: Service | C1: Employee | D1: Customer | E1: Rate | F1: Discount | G1: Total | H1: Category | I1: Payment | J1: Type
E2: =IF($B2="","",IFERROR(INDEX(Services!$C$2:$C$120,MATCH($B2,Services!$D$2:$D$120,0)),"")) | G2: =IF(OR($B2="",NOT(ISNUMBER($E2))),"",$E2-IF($F2="",0,$F2)) | H2: =IF($B2="","",IFERROR(INDEX(Services!$A$2:$A$120,MATCH($B2,Services!$D$2:$D$120,0)),"")) | J2: =IF($B2="","",IFERROR(INDEX(Services!$E$2:$E$120,MATCH($B2,Services!$D$2:$D$120,0)),""))
E3: =IF($B3="","",IFERROR(INDEX(Services!$C$2:$C$120,MATCH($B3,Services!$D$2:$D$120,0)),"")) | G3: =IF(OR($B3="",NOT(ISNUMBER($E3))),"",$E3-IF($F3="",0,$F3)) | H3: =IF($B3="","",IFERROR(INDEX(Services!$A$2:$A$120,MATCH($B3,Services!$D$2:$D$120,0)),"")) | J3: =IF($B3="","",IFERROR(INDEX(Services!$E$2:$E$120,MATCH($B3,Services!$D$2:$D$120,0)),""))
E4: =IF($B4="","",IFERROR(INDEX(Services!$C$2:$C$120,MATCH($B4,Services!$D$2:$D$120,0)),"")) | G4: =IF(OR($B4="",NOT(ISNUMBER($E4))),"",$E4-IF($F4="",0,$F4)) | H4: =IF($B4="","",IFERROR(INDEX(Services!$A$2:$A$120,MATCH($B4,Services!$D$2:$D$120,0)),"")) | J4: =IF($B4="","",IFERROR(INDEX(Services!$E$2:$E$120,MATCH($B4,Services!$D$2:$D$120,0)),""))
E5: =IF($B5="","",IFERROR(INDEX(Services!$C$2:$C$120,MATCH($B5,Services!$D$2:$D$120,0)),"")) | G5: =IF(OR($B5="",NOT(ISNUMBER($E5))),"",$E5-IF($F5="",0,$F5)) | H5: =IF($B5="","",IFERROR(INDEX(Services!$A$2:$A$120,MATCH($B5,Services!$D$2:$D$120,0)),"")) | J5: =IF($B5="","",IFERROR(INDEX(Services!$E$2:$E$120,MATCH($B5,Services!$D$2:$D$120,0)),""))
E6: =IF($B6="","",IFERROR(INDEX(Services!$C$2:$C$120,MATCH($B6,Services!$D$2:$D$120,0)),"")) | G6: =IF(OR($B6="",NOT(ISNUMBER($E6))),"",$E6-IF($F6="",0,$F6)) | H6: =IF($B6="","",IFERROR(INDEX(Services!$A$2:$A$120,MATCH($B6,Services!$D$2:$D$120,0)),"")) | J6: =IF($B6="","",IFERROR(INDEX(Services!$E$2:$E$120,MATCH($B6,Services!$D$2:$D$120,0)),""))
E7: =IF($B7="","",IFERROR(INDEX(Services!$C$2:$C$120,MATCH($B7,Services!$D$2:$D$120,0)),"")) | G7: =IF(OR($B7="",NOT(ISNUMBER($E7))),"",$E7-IF($F7="",0,$F7)) | H7: =IF($B7="","",IFERROR(INDEX(Services!$A$2:$A$120,MATCH($B7,Services!$D$2:$D$120,0)),"")) | J7: =IF($B7="","",IFERROR(INDEX(Services!$E$2:$E$120,MATCH($B7,Services!$D$2:$D$120,0)),""))
E8: =IF($B8="","",IFERROR(INDEX(Services!$C$2:$C$120,MATCH($B8,Services!$D$2:$D$120,0)),"")) | G8: =IF(OR($B8="",NOT(ISNUMBER($E8))),"",$E8-IF($F8="",0,$F8)) | H8: =IF($B8="","",IFERROR(INDEX(Services!$A$2:$A$120,MATCH($B8,Services!$D$2:$D$120,0)),"")) | J8: =IF($B8="","",IFERROR(INDEX(Services!$E$2:$E$120,MATCH($B8,Services!$D$2:$D$120,0)),""))
E9: =IF($B9="","",IFERROR(INDEX(Services!$C$2:$C$120,MATCH($B9,Services!$D$2:$D$120,0)),"")) | G9: =IF(OR($B9="",NOT(ISNUMBER($E9))),"",$E9-IF($F9="",0,$F9)) | H9: =IF($B9="","",IFERROR(INDEX(Services!$A$2:$A$120,MATCH($B9,Services!$D$2:$D$120,0)),"")) | J9: =IF($B9="","",IFERROR(INDEX(Services!$E$2:$E$120,MATCH($B9,Services!$D$2:$D$120,0)),""))
E10: =IF($B10="","",IFERROR(INDEX(Services!$C$2:$C$120,MATCH($B10,Services!$D$2:$D$120,0)),"")) | G10: =IF(OR($B10="",NOT(ISNUMBER($E10))),"",$E10-IF($F10="",0,$F10)) | H10: =IF($B10="","",IFERROR(INDEX(Services!$A$2:$A$120,MATCH($B10,Services!$D$2:$D$120,0)),"")) | J10: =IF($B10="","",IFERROR(INDEX(Services!$E$2:$E$120,MATCH($B10,Services!$D$2:$D$120,0)),""))
E11: =IF($B11="","",IFERROR(INDEX(Services!$C$2:$C$120,MATCH($B11,Services!$D$2:$D$120,0)),"")) | G11: =IF(OR($B11="",NOT(ISNUMBER($E11))),"",$E11-IF($F11="",0,$F11)) | H11: =IF($B11="","",IFERROR(INDEX(Services!$A$2:$A$120,MATCH($B11,Services!$D$2:$D$120,0)),"")) | J11: =IF($B11="","",IFERROR(INDEX(Services!$E$2:$E$120,MATCH($B11,Services!$D$2:$D$120,0)),""))
E12: =IF($B12="","",IFERROR(INDEX(Services!$C$2:$C$120,MATCH($B12,Services!$D$2:$D$120,0)),"")) | G12: =IF(OR($B12="",NOT(ISNUMBER($E12))),"",$E12-IF($F12="",0,$F12)) | H12: =IF($B12="","",IFERROR(INDEX(Services!$A$2:$A$120,MATCH($B12,Services!$D$2:$D$120,0)),"")) | J12: =IF($B12="","",IFERROR(INDEX(Services!$E$2:$E$120,MATCH($B12,Services!$D$2:$D$120,0)),""))
E13: =IF($B13="","",IFERROR(INDEX(Services!$C$2:$C$120,MATCH($B13,Services!$D$2:$D$120,0)),"")) | G13: =IF(OR($B13="",NOT(ISNUMBER($E13))),"",$E13-IF($F13="",0,$F13)) | H13: =IF($B13="","",IFERROR(INDEX(Services!$A$2:$A$120,MATCH($B13,Services!$D$2:$D$120,0)),"")) | J13: =IF($B13="","",IFERROR(INDEX(Services!$E$2:$E$120,MATCH($B13,Services!$D$2:$D$120,0)),""))
... E2001: =IF($B2001="","",IFERROR(INDEX(Services!$C$2:$C$120,MATCH($B2001,Services!$D$2:$D$120,0)),"")) | G2001: =IF(OR($B2001="",NOT(ISNUMBER($E2001))),"",$E2001-IF($F2001="",0,$F2001)) | H2001: =IF($B2001="","",IFERROR(INDEX(Services!$A$2:$A$120,MATCH($B2001,Services!$D$2:$D$120,0)),"")) | J2001: =IF($B2001="","",IFERROR(INDEX(Services!$E$2:$E$120,MATCH($B2001,Services!$D$2:$D$120,0)),""))

Sheet Customer Database
A1: Name | B1: Number | C1: Visits | D1: Total Spent | E1: Last Visit | F1: Days Since | G1: Status | H1: Avg Ticket | I1: Birthday | J1: Anniversary | K1: Gender | L1: Area | M1: Source | N1: RFM Score | O1: Segment | P1: Bday This Month | Q1: First Visit | R1: Avg Gap (days)
C2: =IF($A2="","",COUNTIF('Daily tracking'!$D$2:$D$2001,$A2)) | D2: =IF($A2="","",SUMIF('Daily tracking'!$D$2:$D$2001,$A2,'Daily tracking'!$G$2:$G$2001)) | E2: =IF($A2="","",IF($C2=0,"",_xlfn.MAXIFS('Daily tracking'!$A$2:$A$2001,'Daily tracking'!$D$2:$D$2001,$A2))) | F2: =IF(OR($A2="",$E2=""),"",TODAY()-$E2) | G2: =IF($A2="","",IF($C2=0,"No visits",IF($F2>90,"Lapsed",IF($F2>35,"At risk",IF($C2>=4,"Loyal","Active"))))) | H2: =IF(OR($A2="",$C2=0),"",$D2/$C2) | N2: =IF($A2="","",IF($C2=0,0,(IF($F2<=15,5,IF($F2<=30,4,IF($F2<=45,3,IF($F2<=90,2,1))))+IF($C2>=10,5,IF($C2>=6,4,IF($C2>=4,3,IF($C2>=2,2,1))))+IF($D2>=20000,5,IF($D2>=10000,4,IF($D2>=5000,3,IF($D2>=2000,2,1))))))) | O2: =IF($A2="","",IF($C2=0,"No visits",IF($N2>=13,"VIP",IF($N2>=10,"High value",IF($N2>=7,"Regular",IF($N2>=4,"Occasional","Low")))))) | P2: =IF(OR($A2="",$I2=""),"",IF(MONTH($I2)=MONTH(TODAY()),"Yes","")) | Q2: =IF($A2="","",IF($C2=0,"",_xlfn.MINIFS('Daily tracking'!$A$2:$A$2001,'Daily tracking'!$D$2:$D$2001,$A2))) | R2: =IF(OR($A2="",$C2<2),"",($E2-$Q2)/($C2-1))
C3: =IF($A3="","",COUNTIF('Daily tracking'!$D$2:$D$2001,$A3)) | D3: =IF($A3="","",SUMIF('Daily tracking'!$D$2:$D$2001,$A3,'Daily tracking'!$G$2:$G$2001)) | E3: =IF($A3="","",IF($C3=0,"",_xlfn.MAXIFS('Daily tracking'!$A$2:$A$2001,'Daily tracking'!$D$2:$D$2001,$A3))) | F3: =IF(OR($A3="",$E3=""),"",TODAY()-$E3) | G3: =IF($A3="","",IF($C3=0,"No visits",IF($F3>90,"Lapsed",IF($F3>35,"At risk",IF($C3>=4,"Loyal","Active"))))) | H3: =IF(OR($A3="",$C3=0),"",$D3/$C3) | N3: =IF($A3="","",IF($C3=0,0,(IF($F3<=15,5,IF($F3<=30,4,IF($F3<=45,3,IF($F3<=90,2,1))))+IF($C3>=10,5,IF($C3>=6,4,IF($C3>=4,3,IF($C3>=2,2,1))))+IF($D3>=20000,5,IF($D3>=10000,4,IF($D3>=5000,3,IF($D3>=2000,2,1))))))) | O3: =IF($A3="","",IF($C3=0,"No visits",IF($N3>=13,"VIP",IF($N3>=10,"High value",IF($N3>=7,"Regular",IF($N3>=4,"Occasional","Low")))))) | P3: =IF(OR($A3="",$I3=""),"",IF(MONTH($I3)=MONTH(TODAY()),"Yes","")) | Q3: =IF($A3="","",IF($C3=0,"",_xlfn.MINIFS('Daily tracking'!$A$2:$A$2001,'Daily tracking'!$D$2:$D$2001,$A3))) | R3: =IF(OR($A3="",$C3<2),"",($E3-$Q3)/($C3-1))
C4: =IF($A4="","",COUNTIF('Daily tracking'!$D$2:$D$2001,$A4)) | D4: =IF($A4="","",SUMIF('Daily tracking'!$D$2:$D$2001,$A4,'Daily tracking'!$G$2:$G$2001)) | E4: =IF($A4="","",IF($C4=0,"",_xlfn.MAXIFS('Daily tracking'!$A$2:$A$2001,'Daily tracking'!$D$2:$D$2001,$A4))) | F4: =IF(OR($A4="",$E4=""),"",TODAY()-$E4) | G4: =IF($A4="","",IF($C4=0,"No visits",IF($F4>90,"Lapsed",IF($F4>35,"At risk",IF($C4>=4,"Loyal","Active"))))) | H4: =IF(OR($A4="",$C4=0),"",$D4/$C4) | N4: =IF($A4="","",IF($C4=0,0,(IF($F4<=15,5,IF($F4<=30,4,IF($F4<=45,3,IF($F4<=90,2,1))))+IF($C4>=10,5,IF($C4>=6,4,IF($C4>=4,3,IF($C4>=2,2,1))))+IF($D4>=20000,5,IF($D4>=10000,4,IF($D4>=5000,3,IF($D4>=2000,2,1))))))) | O4: =IF($A4="","",IF($C4=0,"No visits",IF($N4>=13,"VIP",IF($N4>=10,"High value",IF($N4>=7,"Regular",IF($N4>=4,"Occasional","Low")))))) | P4: =IF(OR($A4="",$I4=""),"",IF(MONTH($I4)=MONTH(TODAY()),"Yes","")) | Q4: =IF($A4="","",IF($C4=0,"",_xlfn.MINIFS('Daily tracking'!$A$2:$A$2001,'Daily tracking'!$D$2:$D$2001,$A4))) | R4: =IF(OR($A4="",$C4<2),"",($E4-$Q4)/($C4-1))
C5: =IF($A5="","",COUNTIF('Daily tracking'!$D$2:$D$2001,$A5)) | D5: =IF($A5="","",SUMIF('Daily tracking'!$D$2:$D$2001,$A5,'Daily tracking'!$G$2:$G$2001)) | E5: =IF($A5="","",IF($C5=0,"",_xlfn.MAXIFS('Daily tracking'!$A$2:$A$2001,'Daily tracking'!$D$2:$D$2001,$A5))) | F5: =IF(OR($A5="",$E5=""),"",TODAY()-$E5) | G5: =IF($A5="","",IF($C5=0,"No visits",IF($F5>90,"Lapsed",IF($F5>35,"At risk",IF($C5>=4,"Loyal","Active"))))) | H5: =IF(OR($A5="",$C5=0),"",$D5/$C5) | N5: =IF($A5="","",IF($C5=0,0,(IF($F5<=15,5,IF($F5<=30,4,IF($F5<=45,3,IF($F5<=90,2,1))))+IF($C5>=10,5,IF($C5>=6,4,IF($C5>=4,3,IF($C5>=2,2,1))))+IF($D5>=20000,5,IF($D5>=10000,4,IF($D5>=5000,3,IF($D5>=2000,2,1))))))) | O5: =IF($A5="","",IF($C5=0,"No visits",IF($N5>=13,"VIP",IF($N5>=10,"High value",IF($N5>=7,"Regular",IF($N5>=4,"Occasional","Low")))))) | P5: =IF(OR($A5="",$I5=""),"",IF(MONTH($I5)=MONTH(TODAY()),"Yes","")) | Q5: =IF($A5="","",IF($C5=0,"",_xlfn.MINIFS('Daily tracking'!$A$2:$A$2001,'Daily tracking'!$D$2:$D$2001,$A5))) | R5: =IF(OR($A5="",$C5<2),"",($E5-$Q5)/($C5-1))
C6: =IF($A6="","",COUNTIF('Daily tracking'!$D$2:$D$2001,$A6)) | D6: =IF($A6="","",SUMIF('Daily tracking'!$D$2:$D$2001,$A6,'Daily tracking'!$G$2:$G$2001)) | E6: =IF($A6="","",IF($C6=0,"",_xlfn.MAXIFS('Daily tracking'!$A$2:$A$2001,'Daily tracking'!$D$2:$D$2001,$A6))) | F6: =IF(OR($A6="",$E6=""),"",TODAY()-$E6) | G6: =IF($A6="","",IF($C6=0,"No visits",IF($F6>90,"Lapsed",IF($F6>35,"At risk",IF($C6>=4,"Loyal","Active"))))) | H6: =IF(OR($A6="",$C6=0),"",$D6/$C6) | N6: =IF($A6="","",IF($C6=0,0,(IF($F6<=15,5,IF($F6<=30,4,IF($F6<=45,3,IF($F6<=90,2,1))))+IF($C6>=10,5,IF($C6>=6,4,IF($C6>=4,3,IF($C6>=2,2,1))))+IF($D6>=20000,5,IF($D6>=10000,4,IF($D6>=5000,3,IF($D6>=2000,2,1))))))) | O6: =IF($A6="","",IF($C6=0,"No visits",IF($N6>=13,"VIP",IF($N6>=10,"High value",IF($N6>=7,"Regular",IF($N6>=4,"Occasional","Low")))))) | P6: =IF(OR($A6="",$I6=""),"",IF(MONTH($I6)=MONTH(TODAY()),"Yes","")) | Q6: =IF($A6="","",IF($C6=0,"",_xlfn.MINIFS('Daily tracking'!$A$2:$A$2001,'Daily tracking'!$D$2:$D$2001,$A6))) | R6: =IF(OR($A6="",$C6<2),"",($E6-$Q6)/($C6-1))
C7: =IF($A7="","",COUNTIF('Daily tracking'!$D$2:$D$2001,$A7)) | D7: =IF($A7="","",SUMIF('Daily tracking'!$D$2:$D$2001,$A7,'Daily tracking'!$G$2:$G$2001)) | E7: =IF($A7="","",IF($C7=0,"",_xlfn.MAXIFS('Daily tracking'!$A$2:$A$2001,'Daily tracking'!$D$2:$D$2001,$A7))) | F7: =IF(OR($A7="",$E7=""),"",TODAY()-$E7) | G7: =IF($A7="","",IF($C7=0,"No visits",IF($F7>90,"Lapsed",IF($F7>35,"At risk",IF($C7>=4,"Loyal","Active"))))) | H7: =IF(OR($A7="",$C7=0),"",$D7/$C7) | N7: =IF($A7="","",IF($C7=0,0,(IF($F7<=15,5,IF($F7<=30,4,IF($F7<=45,3,IF($F7<=90,2,1))))+IF($C7>=10,5,IF($C7>=6,4,IF($C7>=4,3,IF($C7>=2,2,1))))+IF($D7>=20000,5,IF($D7>=10000,4,IF($D7>=5000,3,IF($D7>=2000,2,1))))))) | O7: =IF($A7="","",IF($C7=0,"No visits",IF($N7>=13,"VIP",IF($N7>=10,"High value",IF($N7>=7,"Regular",IF($N7>=4,"Occasional","Low")))))) | P7: =IF(OR($A7="",$I7=""),"",IF(MONTH($I7)=MONTH(TODAY()),"Yes","")) | Q7: =IF($A7="","",IF($C7=0,"",_xlfn.MINIFS('Daily tracking'!$A$2:$A$2001,'Daily tracking'!$D$2:$D$2001,$A7))) | R7: =IF(OR($A7="",$C7<2),"",($E7-$Q7)/($C7-1))
C8: =IF($A8="","",COUNTIF('Daily tracking'!$D$2:$D$2001,$A8)) | D8: =IF($A8="","",SUMIF('Daily tracking'!$D$2:$D$2001,$A8,'Daily tracking'!$G$2:$G$2001)) | E8: =IF($A8="","",IF($C8=0,"",_xlfn.MAXIFS('Daily tracking'!$A$2:$A$2001,'Daily tracking'!$D$2:$D$2001,$A8))) | F8: =IF(OR($A8="",$E8=""),"",TODAY()-$E8) | G8: =IF($A8="","",IF($C8=0,"No visits",IF($F8>90,"Lapsed",IF($F8>35,"At risk",IF($C8>=4,"Loyal","Active"))))) | H8: =IF(OR($A8="",$C8=0),"",$D8/$C8) | N8: =IF($A8="","",IF($C8=0,0,(IF($F8<=15,5,IF($F8<=30,4,IF($F8<=45,3,IF($F8<=90,2,1))))+IF($C8>=10,5,IF($C8>=6,4,IF($C8>=4,3,IF($C8>=2,2,1))))+IF($D8>=20000,5,IF($D8>=10000,4,IF($D8>=5000,3,IF($D8>=2000,2,1))))))) | O8: =IF($A8="","",IF($C8=0,"No visits",IF($N8>=13,"VIP",IF($N8>=10,"High value",IF($N8>=7,"Regular",IF($N8>=4,"Occasional","Low")))))) | P8: =IF(OR($A8="",$I8=""),"",IF(MONTH($I8)=MONTH(TODAY()),"Yes","")) | Q8: =IF($A8="","",IF($C8=0,"",_xlfn.MINIFS('Daily tracking'!$A$2:$A$2001,'Daily tracking'!$D$2:$D$2001,$A8))) | R8: =IF(OR($A8="",$C8<2),"",($E8-$Q8)/($C8-1))
C9: =IF($A9="","",COUNTIF('Daily tracking'!$D$2:$D$2001,$A9)) | D9: =IF($A9="","",SUMIF('Daily tracking'!$D$2:$D$2001,$A9,'Daily tracking'!$G$2:$G$2001)) | E9: =IF($A9="","",IF($C9=0,"",_xlfn.MAXIFS('Daily tracking'!$A$2:$A$2001,'Daily tracking'!$D$2:$D$2001,$A9))) | F9: =IF(OR($A9="",$E9=""),"",TODAY()-$E9) | G9: =IF($A9="","",IF($C9=0,"No visits",IF($F9>90,"Lapsed",IF($F9>35,"At risk",IF($C9>=4,"Loyal","Active"))))) | H9: =IF(OR($A9="",$C9=0),"",$D9/$C9) | N9: =IF($A9="","",IF($C9=0,0,(IF($F9<=15,5,IF($F9<=30,4,IF($F9<=45,3,IF($F9<=90,2,1))))+IF($C9>=10,5,IF($C9>=6,4,IF($C9>=4,3,IF($C9>=2,2,1))))+IF($D9>=20000,5,IF($D9>=10000,4,IF($D9>=5000,3,IF($D9>=2000,2,1))))))) | O9: =IF($A9="","",IF($C9=0,"No visits",IF($N9>=13,"VIP",IF($N9>=10,"High value",IF($N9>=7,"Regular",IF($N9>=4,"Occasional","Low")))))) | P9: =IF(OR($A9="",$I9=""),"",IF(MONTH($I9)=MONTH(TODAY()),"Yes","")) | Q9: =IF($A9="","",IF($C9=0,"",_xlfn.MINIFS('Daily tracking'!$A$2:$A$2001,'Daily tracking'!$D$2:$D$2001,$A9))) | R9: =IF(OR($A9="",$C9<2),"",($E9-$Q9)/($C9-1))
C10: =IF($A10="","",COUNTIF('Daily tracking'!$D$2:$D$2001,$A10)) | D10: =IF($A10="","",SUMIF('Daily tracking'!$D$2:$D$2001,$A10,'Daily tracking'!$G$2:$G$2001)) | E10: =IF($A10="","",IF($C10=0,"",_xlfn.MAXIFS('Daily tracking'!$A$2:$A$2001,'Daily tracking'!$D$2:$D$2001,$A10))) | F10: =IF(OR($A10="",$E10=""),"",TODAY()-$E10) | G10: =IF($A10="","",IF($C10=0,"No visits",IF($F10>90,"Lapsed",IF($F10>35,"At risk",IF($C10>=4,"Loyal","Active"))))) | H10: =IF(OR($A10="",$C10=0),"",$D10/$C10) | N10: =IF($A10="","",IF($C10=0,0,(IF($F10<=15,5,IF($F10<=30,4,IF($F10<=45,3,IF($F10<=90,2,1))))+IF($C10>=10,5,IF($C10>=6,4,IF($C10>=4,3,IF($C10>=2,2,1))))+IF($D10>=20000,5,IF($D10>=10000,4,IF($D10>=5000,3,IF($D10>=2000,2,1))))))) | O10: =IF($A10="","",IF($C10=0,"No visits",IF($N10>=13,"VIP",IF($N10>=10,"High value",IF($N10>=7,"Regular",IF($N10>=4,"Occasional","Low")))))) | P10: =IF(OR($A10="",$I10=""),"",IF(MONTH($I10)=MONTH(TODAY()),"Yes","")) | Q10: =IF($A10="","",IF($C10=0,"",_xlfn.MINIFS('Daily tracking'!$A$2:$A$2001,'Daily tracking'!$D$2:$D$2001,$A10))) | R10: =IF(OR($A10="",$C10<2),"",($E10-$Q10)/($C10-1))
C11: =IF($A11="","",COUNTIF('Daily tracking'!$D$2:$D$2001,$A11)) | D11: =IF($A11="","",SUMIF('Daily tracking'!$D$2:$D$2001,$A11,'Daily tracking'!$G$2:$G$2001)) | E11: =IF($A11="","",IF($C11=0,"",_xlfn.MAXIFS('Daily tracking'!$A$2:$A$2001,'Daily tracking'!$D$2:$D$2001,$A11))) | F11: =IF(OR($A11="",$E11=""),"",TODAY()-$E11) | G11: =IF($A11="","",IF($C11=0,"No visits",IF($F11>90,"Lapsed",IF($F11>35,"At risk",IF($C11>=4,"Loyal","Active"))))) | H11: =IF(OR($A11="",$C11=0),"",$D11/$C11) | N11: =IF($A11="","",IF($C11=0,0,(IF($F11<=15,5,IF($F11<=30,4,IF($F11<=45,3,IF($F11<=90,2,1))))+IF($C11>=10,5,IF($C11>=6,4,IF($C11>=4,3,IF($C11>=2,2,1))))+IF($D11>=20000,5,IF($D11>=10000,4,IF($D11>=5000,3,IF($D11>=2000,2,1))))))) | O11: =IF($A11="","",IF($C11=0,"No visits",IF($N11>=13,"VIP",IF($N11>=10,"High value",IF($N11>=7,"Regular",IF($N11>=4,"Occasional","Low")))))) | P11: =IF(OR($A11="",$I11=""),"",IF(MONTH($I11)=MONTH(TODAY()),"Yes","")) | Q11: =IF($A11="","",IF($C11=0,"",_xlfn.MINIFS('Daily tracking'!$A$2:$A$2001,'Daily tracking'!$D$2:$D$2001,$A11))) | R11: =IF(OR($A11="",$C11<2),"",($E11-$Q11)/($C11-1))
C12: =IF($A12="","",COUNTIF('Daily tracking'!$D$2:$D$2001,$A12)) | D12: =IF($A12="","",SUMIF('Daily tracking'!$D$2:$D$2001,$A12,'Daily tracking'!$G$2:$G$2001)) | E12: =IF($A12="","",IF($C12=0,"",_xlfn.MAXIFS('Daily tracking'!$A$2:$A$2001,'Daily tracking'!$D$2:$D$2001,$A12))) | F12: =IF(OR($A12="",$E12=""),"",TODAY()-$E12) | G12: =IF($A12="","",IF($C12=0,"No visits",IF($F12>90,"Lapsed",IF($F12>35,"At risk",IF($C12>=4,"Loyal","Active"))))) | H12: =IF(OR($A12="",$C12=0),"",$D12/$C12) | N12: =IF($A12="","",IF($C12=0,0,(IF($F12<=15,5,IF($F12<=30,4,IF($F12<=45,3,IF($F12<=90,2,1))))+IF($C12>=10,5,IF($C12>=6,4,IF($C12>=4,3,IF($C12>=2,2,1))))+IF($D12>=20000,5,IF($D12>=10000,4,IF($D12>=5000,3,IF($D12>=2000,2,1))))))) | O12: =IF($A12="","",IF($C12=0,"No visits",IF($N12>=13,"VIP",IF($N12>=10,"High value",IF($N12>=7,"Regular",IF($N12>=4,"Occasional","Low")))))) | P12: =IF(OR($A12="",$I12=""),"",IF(MONTH($I12)=MONTH(TODAY()),"Yes","")) | Q12: =IF($A12="","",IF($C12=0,"",_xlfn.MINIFS('Daily tracking'!$A$2:$A$2001,'Daily tracking'!$D$2:$D$2001,$A12))) | R12: =IF(OR($A12="",$C12<2),"",($E12-$Q12)/($C12-1))
C13: =IF($A13="","",COUNTIF('Daily tracking'!$D$2:$D$2001,$A13)) | D13: =IF($A13="","",SUMIF('Daily tracking'!$D$2:$D$2001,$A13,'Daily tracking'!$G$2:$G$2001)) | E13: =IF($A13="","",IF($C13=0,"",_xlfn.MAXIFS('Daily tracking'!$A$2:$A$2001,'Daily tracking'!$D$2:$D$2001,$A13))) | F13: =IF(OR($A13="",$E13=""),"",TODAY()-$E13) | G13: =IF($A13="","",IF($C13=0,"No visits",IF($F13>90,"Lapsed",IF($F13>35,"At risk",IF($C13>=4,"Loyal","Active"))))) | H13: =IF(OR($A13="",$C13=0),"",$D13/$C13) | N13: =IF($A13="","",IF($C13=0,0,(IF($F13<=15,5,IF($F13<=30,4,IF($F13<=45,3,IF($F13<=90,2,1))))+IF($C13>=10,5,IF($C13>=6,4,IF($C13>=4,3,IF($C13>=2,2,1))))+IF($D13>=20000,5,IF($D13>=10000,4,IF($D13>=5000,3,IF($D13>=2000,2,1))))))) | O13: =IF($A13="","",IF($C13=0,"No visits",IF($N13>=13,"VIP",IF($N13>=10,"High value",IF($N13>=7,"Regular",IF($N13>=4,"Occasional","Low")))))) | P13: =IF(OR($A13="",$I13=""),"",IF(MONTH($I13)=MONTH(TODAY()),"Yes","")) | Q13: =IF($A13="","",IF($C13=0,"",_xlfn.MINIFS('Daily tracking'!$A$2:$A$2001,'Daily tracking'!$D$2:$D$2001,$A13))) | R13: =IF(OR($A13="",$C13<2),"",($E13-$Q13)/($C13-1))
... C501: =IF($A501="","",COUNTIF('Daily tracking'!$D$2:$D$2001,$A501)) | D501: =IF($A501="","",SUMIF('Daily tracking'!$D$2:$D$2001,$A501,'Daily tracking'!$G$2:$G$2001)) | E501: =IF($A501="","",IF($C501=0,"",_xlfn.MAXIFS('Daily tracking'!$A$2:$A$2001,'Daily tracking'!$D$2:$D$2001,$A501))) | F501: =IF(OR($A501="",$E501=""),"",TODAY()-$E501) | G501: =IF($A501="","",IF($C501=0,"No visits",IF($F501>90,"Lapsed",IF($F501>35,"At risk",IF($C501>=4,"Loyal","Active"))))) | H501: =IF(OR($A501="",$C501=0),"",$D501/$C501) | N501: =IF($A501="","",IF($C501=0,0,(IF($F501<=15,5,IF($F501<=30,4,IF($F501<=45,3,IF($F501<=90,2,1))))+IF($C501>=10,5,IF($C501>=6,4,IF($C501>=4,3,IF($C501>=2,2,1))))+IF($D501>=20000,5,IF($D501>=10000,4,IF($D501>=5000,3,IF($D501>=2000,2,1))))))) | O501: =IF($A501="","",IF($C501=0,"No visits",IF($N501>=13,"VIP",IF($N501>=10,"High value",IF($N501>=7,"Regular",IF($N501>=4,"Occasional","Low")))))) | P501: =IF(OR($A501="",$I501=""),"",IF(MONTH($I501)=MONTH(TODAY()),"Yes","")) | Q501: =IF($A501="","",IF($C501=0,"",_xlfn.MINIFS('Daily tracking'!$A$2:$A$2001,'Daily tracking'!$D$2:$D$2001,$A501))) | R501: =IF(OR($A501="",$C501<2),"",($E501-$Q501)/($C501-1))

Sheet Services
A1: Category | B1: Service | C1: Price | D1: Service Key | E1: Type | F1: Unit Cost | G1: Revenue | H1: Bookings | I1: Total Cost | J1: Gross Profit | K1: Margin %
A2: Threading | B2: Eyebrow | C2: 30 | D2: =IF(A2="","",A2&" - "&B2) -> Threading - Eyebrow | E2: Service | G2: =IF($D2="","",SUMIF('Daily tracking'!$B$2:$B$2001,$D2,'Daily tracking'!$G$2:$G$2001)) -> 0 | H2: =IF($D2="","",COUNTIF('Daily tracking'!$B$2:$B$2001,$D2)) -> 0 | I2: =IF($D2="","",$H2*IF($F2="",0,$F2)) -> 0 | J2: =IF($D2="","",$G2-$I2) -> 0 | K2: =IF(OR($D2="",$G2=0),"",$J2/$G2)
A3: Threading | B3: Forehead | C3: 30 | D3: =IF(A3="","",A3&" - "&B3) -> Threading - Forehead | E3: Service | G3: =IF($D3="","",SUMIF('Daily tracking'!$B$2:$B$2001,$D3,'Daily tracking'!$G$2:$G$2001)) -> 0 | H3: =IF($D3="","",COUNTIF('Daily tracking'!$B$2:$B$2001,$D3)) -> 0 | I3: =IF($D3="","",$H3*IF($F3="",0,$F3)) -> 0 | J3: =IF($D3="","",$G3-$I3) -> 0 | K3: =IF(OR($D3="",$G3=0),"",$J3/$G3)
A4: Threading | B4: Upper lip | C4: 20 | D4: =IF(A4="","",A4&" - "&B4) -> Threading - Upper lip | E4: Service | G4: =IF($D4="","",SUMIF('Daily tracking'!$B$2:$B$2001,$D4,'Daily tracking'!$G$2:$G$2001)) -> 0 | H4: =IF($D4="","",COUNTIF('Daily tracking'!$B$2:$B$2001,$D4)) -> 0 | I4: =IF($D4="","",$H4*IF($F4="",0,$F4)) -> 0 | J4: =IF($D4="","",$G4-$I4) -> 0 | K4: =IF(OR($D4="",$G4=0),"",$J4/$G4)
A5: Threading | B5: Chin | C5: 20 | D5: =IF(A5="","",A5&" - "&B5) -> Threading - Chin | E5: Service | G5: =IF($D5="","",SUMIF('Daily tracking'!$B$2:$B$2001,$D5,'Daily tracking'!$G$2:$G$2001)) -> 0 | H5: =IF($D5="","",COUNTIF('Daily tracking'!$B$2:$B$2001,$D5)) -> 0 | I5: =IF($D5="","",$H5*IF($F5="",0,$F5)) -> 0 | J5: =IF($D5="","",$G5-$I5) -> 0 | K5: =IF(OR($D5="",$G5=0),"",$J5/$G5)
A6: Threading | B6: Full face | C6: 160 | D6: =IF(A6="","",A6&" - "&B6) -> Threading - Full face | E6: Service | G6: =IF($D6="","",SUMIF('Daily tracking'!$B$2:$B$2001,$D6,'Daily tracking'!$G$2:$G$2001)) -> 0 | H6: =IF($D6="","",COUNTIF('Daily tracking'!$B$2:$B$2001,$D6)) -> 0 | I6: =IF($D6="","",$H6*IF($F6="",0,$F6)) -> 0 | J6: =IF($D6="","",$G6-$I6) -> 0 | K6: =IF(OR($D6="",$G6=0),"",$J6/$G6)
A7: Threading | B7: Sidelocks | C7: 50 | D7: =IF(A7="","",A7&" - "&B7) -> Threading - Sidelocks | E7: Service | G7: =IF($D7="","",SUMIF('Daily tracking'!$B$2:$B$2001,$D7,'Daily tracking'!$G$2:$G$2001)) -> 0 | H7: =IF($D7="","",COUNTIF('Daily tracking'!$B$2:$B$2001,$D7)) -> 0 | I7: =IF($D7="","",$H7*IF($F7="",0,$F7)) -> 0 | J7: =IF($D7="","",$G7-$I7) -> 0 | K7: =IF(OR($D7="",$G7=0),"",$J7/$G7)
A8: Waxing | B8: Chin | C8: 80 | D8: =IF(A8="","",A8&" - "&B8) -> Waxing - Chin | E8: Service | G8: =IF($D8="","",SUMIF('Daily tracking'!$B$2:$B$2001,$D8,'Daily tracking'!$G$2:$G$2001)) -> 0 | H8: =IF($D8="","",COUNTIF('Daily tracking'!$B$2:$B$2001,$D8)) -> 0 | I8: =IF($D8="","",$H8*IF($F8="",0,$F8)) -> 0 | J8: =IF($D8="","",$G8-$I8) -> 0 | K8: =IF(OR($D8="",$G8=0),"",$J8/$G8)
A9: Waxing | B9: Upper lip | C9: 60 | D9: =IF(A9="","",A9&" - "&B9) -> Waxing - Upper lip | E9: Service | G9: =IF($D9="","",SUMIF('Daily tracking'!$B$2:$B$2001,$D9,'Daily tracking'!$G$2:$G$2001)) -> 0 | H9: =IF($D9="","",COUNTIF('Daily tracking'!$B$2:$B$2001,$D9)) -> 0 | I9: =IF($D9="","",$H9*IF($F9="",0,$F9)) -> 0 | J9: =IF($D9="","",$G9-$I9) -> 0 | K9: =IF(OR($D9="",$G9=0),"",$J9/$G9)
A10: Waxing | B10: Sidelocks | C10: 80 | D10: =IF(A10="","",A10&" - "&B10) -> Waxing - Sidelocks | E10: Service | G10: =IF($D10="","",SUMIF('Daily tracking'!$B$2:$B$2001,$D10,'Daily tracking'!$G$2:$G$2001)) -> 0 | H10: =IF($D10="","",COUNTIF('Daily tracking'!$B$2:$B$2001,$D10)) -> 0 | I10: =IF($D10="","",$H10*IF($F10="",0,$F10)) -> 0 | J10: =IF($D10="","",$G10-$I10) -> 0 | K10: =IF(OR($D10="",$G10=0),"",$J10/$G10)
A11: Waxing | B11: Neck | C11: 100 | D11: =IF(A11="","",A11&" - "&B11) -> Waxing - Neck | E11: Service | G11: =IF($D11="","",SUMIF('Daily tracking'!$B$2:$B$2001,$D11,'Daily tracking'!$G$2:$G$2001)) -> 0 | H11: =IF($D11="","",COUNTIF('Daily tracking'!$B$2:$B$2001,$D11)) -> 0 | I11: =IF($D11="","",$H11*IF($F11="",0,$F11)) -> 0 | J11: =IF($D11="","",$G11-$I11) -> 0 | K11: =IF(OR($D11="",$G11=0),"",$J11/$G11)
A12: Waxing | B12: Jawline | C12: 80 | D12: =IF(A12="","",A12&" - "&B12) -> Waxing - Jawline | E12: Service | G12: =IF($D12="","",SUMIF('Daily tracking'!$B$2:$B$2001,$D12,'Daily tracking'!$G$2:$G$2001)) -> 0 | H12: =IF($D12="","",COUNTIF('Daily tracking'!$B$2:$B$2001,$D12)) -> 0 | I12: =IF($D12="","",$H12*IF($F12="",0,$F12)) -> 0 | J12: =IF($D12="","",$G12-$I12) -> 0 | K12: =IF(OR($D12="",$G12=0),"",$J12/$G12)
A13: Waxing | B13: Forehead | C13: 80 | D13: =IF(A13="","",A13&" - "&B13) -> Waxing - Forehead | E13: Service | G13: =IF($D13="","",SUMIF('Daily tracking'!$B$2:$B$2001,$D13,'Daily tracking'!$G$2:$G$2001)) -> 0 | H13: =IF($D13="","",COUNTIF('Daily tracking'!$B$2:$B$2001,$D13)) -> 0 | I13: =IF($D13="","",$H13*IF($F13="",0,$F13)) -> 0 | J13: =IF($D13="","",$G13-$I13) -> 0 | K13: =IF(OR($D13="",$G13=0),"",$J13/$G13)
... A86: Facial | B86: Bridal | C86: 2400 | D86: =IF(A86="","",A86&" - "&B86) -> Facial - Bridal | E86: Service | G86: =IF($D86="","",SUMIF('Daily tracking'!$B$2:$B$2001,$D86,'Daily tracking'!$G$2:$G$2001)) -> 0 | H86: =IF($D86="","",COUNTIF('Daily tracking'!$B$2:$B$2001,$D86)) -> 0 | I86: =IF($D86="","",$H86*IF($F86="",0,$F86)) -> 0 | J86: =IF($D86="","",$G86-$I86) -> 0 | K86: =IF(OR($D86="",$G86=0),"",$J86/$G86)
D87: =IF(A87="","",A87&" - "&B87) | G87: =IF($D87="","",SUMIF('Daily tracking'!$B$2:$B$2001,$D87,'Daily tracking'!$G$2:$G$2001)) | H87: =IF($D87="","",COUNTIF('Daily tracking'!$B$2:$B$2001,$D87)) | I87: =IF($D87="","",$H87*IF($F87="",0,$F87)) | J87: =IF($D87="","",$G87-$I87) | K87: =IF(OR($D87="",$G87=0),"",$J87/$G87)
D88: =IF(A88="","",A88&" - "&B88) | G88: =IF($D88="","",SUMIF('Daily tracking'!$B$2:$B$2001,$D88,'Daily tracking'!$G$2:$G$2001)) | H88: =IF($D88="","",COUNTIF('Daily tracking'!$B$2:$B$2001,$D88)) | I88: =IF($D88="","",$H88*IF($F88="",0,$F88)) | J88: =IF($D88="","",$G88-$I88) | K88: =IF(OR($D88="",$G88=0),"",$J88/$G88)
D89: =IF(A89="","",A89&" - "&B89) | G89: =IF($D89="","",SUMIF('Daily tracking'!$B$2:$B$2001,$D89,'Daily tracking'!$G$2:$G$2001)) | H89: =IF($D89="","",COUNTIF('Daily tracking'!$B$2:$B$2001,$D89)) | I89: =IF($D89="","",$H89*IF($F89="",0,$F89)) | J89: =IF($D89="","",$G89-$I89) | K89: =IF(OR($D89="",$G89=0),"",$J89/$G89)
D90: =IF(A90="","",A90&" - "&B90) | G90: =IF($D90="","",SUMIF('Daily tracking'!$B$2:$B$2001,$D90,'Daily tracking'!$G$2:$G$2001)) | H90: =IF($D90="","",COUNTIF('Daily tracking'!$B$2:$B$2001,$D90)) | I90: =IF($D90="","",$H90*IF($F90="",0,$F90)) | J90: =IF($D90="","",$G90-$I90) | K90: =IF(OR($D90="",$G90=0),"",$J90/$G90)
D91: =IF(A91="","",A91&" - "&B91) | G91: =IF($D91="","",SUMIF('Daily tracking'!$B$2:$B$2001,$D91,'Daily tracking'!$G$2:$G$2001)) | H91: =IF($D91="","",COUNTIF('Daily tracking'!$B$2:$B$2001,$D91)) | I91: =IF($D91="","",$H91*IF($F91="",0,$F91)) | J91: =IF($D91="","",$G91-$I91) | K91: =IF(OR($D91="",$G91=0),"",$J91/$G91)
D92: =IF(A92="","",A92&" - "&B92) | G92: =IF($D92="","",SUMIF('Daily tracking'!$B$2:$B$2001,$D92,'Daily tracking'!$G$2:$G$2001)) | H92: =IF($D92="","",COUNTIF('Daily tracking'!$B$2:$B$2001,$D92)) | I92: =IF($D92="","",$H92*IF($F92="",0,$F92)) | J92: =IF($D92="","",$G92-$I92) | K92: =IF(OR($D92="",$G92=0),"",$J92/$G92)
D93: =IF(A93="","",A93&" - "&B93) | G93: =IF($D93="","",SUMIF('Daily tracking'!$B$2:$B$2001,$D93,'Daily tracking'!$G$2:$G$2001)) | H93: =IF($D93="","",COUNTIF('Daily tracking'!$B$2:$B$2001,$D93)) | I93: =IF($D93="","",$H93*IF($F93="",0,$F93)) | J93: =IF($D93="","",$G93-$I93) | K93: =IF(OR($D93="",$G93=0),"",$J93/$G93)
D94: =IF(A94="","",A94&" - "&B94) | G94: =IF($D94="","",SUMIF('Daily tracking'!$B$2:$B$2001,$D94,'Daily tracking'!$G$2:$G$2001)) | H94: =IF($D94="","",COUNTIF('Daily tracking'!$B$2:$B$2001,$D94)) | I94: =IF($D94="","",$H94*IF($F94="",0,$F94)) | J94: =IF($D94="","",$G94-$I94) | K94: =IF(OR($D94="",$G94=0),"",$J94/$G94)
D95: =IF(A95="","",A95&" - "&B95) | G95: =IF($D95="","",SUMIF('Daily tracking'!$B$2:$B$2001,$D95,'Daily tracking'!$G$2:$G$2001)) | H95: =IF($D95="","",COUNTIF('Daily tracking'!$B$2:$B$2001,$D95)) | I95: =IF($D95="","",$H95*IF($F95="",0,$F95)) | J95: =IF($D95="","",$G95-$I95) | K95: =IF(OR($D95="",$G95=0),"",$J95/$G95)
D96: =IF(A96="","",A96&" - "&B96) | G96: =IF($D96="","",SUMIF('Daily tracking'!$B$2:$B$2001,$D96,'Daily tracking'!$G$2:$G$2001)) | H96: =IF($D96="","",COUNTIF('Daily tracking'!$B$2:$B$2001,$D96)) | I96: =IF($D96="","",$H96*IF($F96="",0,$F96)) | J96: =IF($D96="","",$G96-$I96) | K96: =IF(OR($D96="",$G96=0),"",$J96/$G96)
D97: =IF(A97="","",A97&" - "&B97) | G97: =IF($D97="","",SUMIF('Daily tracking'!$B$2:$B$2001,$D97,'Daily tracking'!$G$2:$G$2001)) | H97: =IF($D97="","",COUNTIF('Daily tracking'!$B$2:$B$2001,$D97)) | I97: =IF($D97="","",$H97*IF($F97="",0,$F97)) | J97: =IF($D97="","",$G97-$I97) | K97: =IF(OR($D97="",$G97=0),"",$J97/$G97)
D98: =IF(A98="","",A98&" - "&B98) | G98: =IF($D98="","",SUMIF('Daily tracking'!$B$2:$B$2001,$D98,'Daily tracking'!$G$2:$G$2001)) | H98: =IF($D98="","",COUNTIF('Daily tracking'!$B$2:$B$2001,$D98)) | I98: =IF($D98="","",$H98*IF($F98="",0,$F98)) | J98: =IF($D98="","",$G98-$I98) | K98: =IF(OR($D98="",$G98=0),"",$J98/$G98)
... D120: =IF(A120="","",A120&" - "&B120) | G120: =IF($D120="","",SUMIF('Daily tracking'!$B$2:$B$2001,$D120,'Daily tracking'!$G$2:$G$2001)) | H120: =IF($D120="","",COUNTIF('Daily tracking'!$B$2:$B$2001,$D120)) | I120: =IF($D120="","",$H120*IF($F120="",0,$F120)) | J120: =IF($D120="","",$G120-$I120) | K120: =IF(OR($D120="",$G120=0),"",$J120/$G120)

Sheet Employee
A1: Name | B1: Salary | C1: Services Done | D1: Revenue (All Time) | E1: Revenue (This Month) | F1: Revenue per ₹ Salary | G1: Commission % | H1: Commission (This Month) | I1: Total Payout (This Month)
A2: Rachna | B2: 15000 | C2: =IF($A2="","",COUNTIF('Daily tracking'!$C$2:$C$2001,$A2)) -> 0 | D2: =IF($A2="","",SUMIF('Daily tracking'!$C$2:$C$2001,$A2,'Daily tracking'!$G$2:$G$2001)) -> 0 | E2: =IF($A2="","",SUMIFS('Daily tracking'!$G$2:$G$2001,'Daily tracking'!$C$2:$C$2001,$A2,'Daily tracking'!$A$2:$A$2001,">="&EOMONTH(TODAY(),-1)+1,'Daily tracking'!$A$2:$A$2001,"<="&EOMONTH(TODAY(),0))) -> 0 | F2: =IF(OR($A2="",$B2=0),"",$D2/$B2) -> 0 | H2: =IF($A2="","",$E2*IF($G2="",0,$G2)) -> 0 | I2: =IF($A2="","",IF($B2="",0,$B2)+$H2) -> 15000
A3: Feroz | B3: 22000 | C3: =IF($A3="","",COUNTIF('Daily tracking'!$C$2:$C$2001,$A3)) -> 0 | D3: =IF($A3="","",SUMIF('Daily tracking'!$C$2:$C$2001,$A3,'Daily tracking'!$G$2:$G$2001)) -> 0 | E3: =IF($A3="","",SUMIFS('Daily tracking'!$G$2:$G$2001,'Daily tracking'!$C$2:$C$2001,$A3,'Daily tracking'!$A$2:$A$2001,">="&EOMONTH(TODAY(),-1)+1,'Daily tracking'!$A$2:$A$2001,"<="&EOMONTH(TODAY(),0))) -> 0 | F3: =IF(OR($A3="",$B3=0),"",$D3/$B3) -> 0 | H3: =IF($A3="","",$E3*IF($G3="",0,$G3)) -> 0 | I3: =IF($A3="","",IF($B3="",0,$B3)+$H3) -> 22000
A4: Mona | B4: 4000 | C4: =IF($A4="","",COUNTIF('Daily tracking'!$C$2:$C$2001,$A4)) -> 0 | D4: =IF($A4="","",SUMIF('Daily tracking'!$C$2:$C$2001,$A4,'Daily tracking'!$G$2:$G$2001)) -> 0 | E4: =IF($A4="","",SUMIFS('Daily tracking'!$G$2:$G$2001,'Daily tracking'!$C$2:$C$2001,$A4,'Daily tracking'!$A$2:$A$2001,">="&EOMONTH(TODAY(),-1)+1,'Daily tracking'!$A$2:$A$2001,"<="&EOMONTH(TODAY(),0))) -> 0 | F4: =IF(OR($A4="",$B4=0),"",$D4/$B4) -> 0 | H4: =IF($A4="","",$E4*IF($G4="",0,$G4)) -> 0 | I4: =IF($A4="","",IF($B4="",0,$B4)+$H4) -> 4000
A5: Chandni | B5: 7000 | C5: =IF($A5="","",COUNTIF('Daily tracking'!$C$2:$C$2001,$A5)) -> 0 | D5: =IF($A5="","",SUMIF('Daily tracking'!$C$2:$C$2001,$A5,'Daily tracking'!$G$2:$G$2001)) -> 0 | E5: =IF($A5="","",SUMIFS('Daily tracking'!$G$2:$G$2001,'Daily tracking'!$C$2:$C$2001,$A5,'Daily tracking'!$A$2:$A$2001,">="&EOMONTH(TODAY(),-1)+1,'Daily tracking'!$A$2:$A$2001,"<="&EOMONTH(TODAY(),0))) -> 0 | F5: =IF(OR($A5="",$B5=0),"",$D5/$B5) -> 0 | H5: =IF($A5="","",$E5*IF($G5="",0,$G5)) -> 0 | I5: =IF($A5="","",IF($B5="",0,$B5)+$H5) -> 7000
C6: =IF($A6="","",COUNTIF('Daily tracking'!$C$2:$C$2001,$A6)) | D6: =IF($A6="","",SUMIF('Daily tracking'!$C$2:$C$2001,$A6,'Daily tracking'!$G$2:$G$2001)) | E6: =IF($A6="","",SUMIFS('Daily tracking'!$G$2:$G$2001,'Daily tracking'!$C$2:$C$2001,$A6,'Daily tracking'!$A$2:$A$2001,">="&EOMONTH(TODAY(),-1)+1,'Daily tracking'!$A$2:$A$2001,"<="&EOMONTH(TODAY(),0))) | F6: =IF(OR($A6="",$B6=0),"",$D6/$B6) | H6: =IF($A6="","",$E6*IF($G6="",0,$G6)) | I6: =IF($A6="","",IF($B6="",0,$B6)+$H6)
C7: =IF($A7="","",COUNTIF('Daily tracking'!$C$2:$C$2001,$A7)) | D7: =IF($A7="","",SUMIF('Daily tracking'!$C$2:$C$2001,$A7,'Daily tracking'!$G$2:$G$2001)) | E7: =IF($A7="","",SUMIFS('Daily tracking'!$G$2:$G$2001,'Daily tracking'!$C$2:$C$2001,$A7,'Daily tracking'!$A$2:$A$2001,">="&EOMONTH(TODAY(),-1)+1,'Daily tracking'!$A$2:$A$2001,"<="&EOMONTH(TODAY(),0))) | F7: =IF(OR($A7="",$B7=0),"",$D7/$B7) | H7: =IF($A7="","",$E7*IF($G7="",0,$G7)) | I7: =IF($A7="","",IF($B7="",0,$B7)+$H7)
C8: =IF($A8="","",COUNTIF('Daily tracking'!$C$2:$C$2001,$A8)) | D8: =IF($A8="","",SUMIF('Daily tracking'!$C$2:$C$2001,$A8,'Daily tracking'!$G$2:$G$2001)) | E8: =IF($A8="","",SUMIFS('Daily tracking'!$G$2:$G$2001,'Daily tracking'!$C$2:$C$2001,$A8,'Daily tracking'!$A$2:$A$2001,">="&EOMONTH(TODAY(),-1)+1,'Daily tracking'!$A$2:$A$2001,"<="&EOMONTH(TODAY(),0))) | F8: =IF(OR($A8="",$B8=0),"",$D8/$B8) | H8: =IF($A8="","",$E8*IF($G8="",0,$G8)) | I8: =IF($A8="","",IF($B8="",0,$B8)+$H8)
C9: =IF($A9="","",COUNTIF('Daily tracking'!$C$2:$C$2001,$A9)) | D9: =IF($A9="","",SUMIF('Daily tracking'!$C$2:$C$2001,$A9,'Daily tracking'!$G$2:$G$2001)) | E9: =IF($A9="","",SUMIFS('Daily tracking'!$G$2:$G$2001,'Daily tracking'!$C$2:$C$2001,$A9,'Daily tracking'!$A$2:$A$2001,">="&EOMONTH(TODAY(),-1)+1,'Daily tracking'!$A$2:$A$2001,"<="&EOMONTH(TODAY(),0))) | F9: =IF(OR($A9="",$B9=0),"",$D9/$B9) | H9: =IF($A9="","",$E9*IF($G9="",0,$G9)) | I9: =IF($A9="","",IF($B9="",0,$B9)+$H9)
C10: =IF($A10="","",COUNTIF('Daily tracking'!$C$2:$C$2001,$A10)) | D10: =IF($A10="","",SUMIF('Daily tracking'!$C$2:$C$2001,$A10,'Daily tracking'!$G$2:$G$2001)) | E10: =IF($A10="","",SUMIFS('Daily tracking'!$G$2:$G$2001,'Daily tracking'!$C$2:$C$2001,$A10,'Daily tracking'!$A$2:$A$2001,">="&EOMONTH(TODAY(),-1)+1,'Daily tracking'!$A$2:$A$2001,"<="&EOMONTH(TODAY(),0))) | F10: =IF(OR($A10="",$B10=0),"",$D10/$B10) | H10: =IF($A10="","",$E10*IF($G10="",0,$G10)) | I10: =IF($A10="","",IF($B10="",0,$B10)+$H10)
C11: =IF($A11="","",COUNTIF('Daily tracking'!$C$2:$C$2001,$A11)) | D11: =IF($A11="","",SUMIF('Daily tracking'!$C$2:$C$2001,$A11,'Daily tracking'!$G$2:$G$2001)) | E11: =IF($A11="","",SUMIFS('Daily tracking'!$G$2:$G$2001,'Daily tracking'!$C$2:$C$2001,$A11,'Daily tracking'!$A$2:$A$2001,">="&EOMONTH(TODAY(),-1)+1,'Daily tracking'!$A$2:$A$2001,"<="&EOMONTH(TODAY(),0))) | F11: =IF(OR($A11="",$B11=0),"",$D11/$B11) | H11: =IF($A11="","",$E11*IF($G11="",0,$G11)) | I11: =IF($A11="","",IF($B11="",0,$B11)+$H11)
C12: =IF($A12="","",COUNTIF('Daily tracking'!$C$2:$C$2001,$A12)) | D12: =IF($A12="","",SUMIF('Daily tracking'!$C$2:$C$2001,$A12,'Daily tracking'!$G$2:$G$2001)) | E12: =IF($A12="","",SUMIFS('Daily tracking'!$G$2:$G$2001,'Daily tracking'!$C$2:$C$2001,$A12,'Daily tracking'!$A$2:$A$2001,">="&EOMONTH(TODAY(),-1)+1,'Daily tracking'!$A$2:$A$2001,"<="&EOMONTH(TODAY(),0))) | F12: =IF(OR($A12="",$B12=0),"",$D12/$B12) | H12: =IF($A12="","",$E12*IF($G12="",0,$G12)) | I12: =IF($A12="","",IF($B12="",0,$B12)+$H12)
C13: =IF($A13="","",COUNTIF('Daily tracking'!$C$2:$C$2001,$A13)) | D13: =IF($A13="","",SUMIF('Daily tracking'!$C$2:$C$2001,$A13,'Daily tracking'!$G$2:$G$2001)) | E13: =IF($A13="","",SUMIFS('Daily tracking'!$G$2:$G$2001,'Daily tracking'!$C$2:$C$2001,$A13,'Daily tracking'!$A$2:$A$2001,">="&EOMONTH(TODAY(),-1)+1,'Daily tracking'!$A$2:$A$2001,"<="&EOMONTH(TODAY(),0))) | F13: =IF(OR($A13="",$B13=0),"",$D13/$B13) | H13: =IF($A13="","",$E13*IF($G13="",0,$G13)) | I13: =IF($A13="","",IF($B13="",0,$B13)+$H13)
C14: =IF($A14="","",COUNTIF('Daily tracking'!$C$2:$C$2001,$A14)) | D14: =IF($A14="","",SUMIF('Daily tracking'!$C$2:$C$2001,$A14,'Daily tracking'!$G$2:$G$2001)) | E14: =IF($A14="","",SUMIFS('Daily tracking'!$G$2:$G$2001,'Daily tracking'!$C$2:$C$2001,$A14,'Daily tracking'!$A$2:$A$2001,">="&EOMONTH(TODAY(),-1)+1,'Daily tracking'!$A$2:$A$2001,"<="&EOMONTH(TODAY(),0))) | F14: =IF(OR($A14="",$B14=0),"",$D14/$B14) | H14: =IF($A14="","",$E14*IF($G14="",0,$G14)) | I14: =IF($A14="","",IF($B14="",0,$B14)+$H14)
C15: =IF($A15="","",COUNTIF('Daily tracking'!$C$2:$C$2001,$A15)) | D15: =IF($A15="","",SUMIF('Daily tracking'!$C$2:$C$2001,$A15,'Daily tracking'!$G$2:$G$2001)) | E15: =IF($A15="","",SUMIFS('Daily tracking'!$G$2:$G$2001,'Daily tracking'!$C$2:$C$2001,$A15,'Daily tracking'!$A$2:$A$2001,">="&EOMONTH(TODAY(),-1)+1,'Daily tracking'!$A$2:$A$2001,"<="&EOMONTH(TODAY(),0))) | F15: =IF(OR($A15="",$B15=0),"",$D15/$B15) | H15: =IF($A15="","",$E15*IF($G15="",0,$G15)) | I15: =IF($A15="","",IF($B15="",0,$B15)+$H15)
C16: =IF($A16="","",COUNTIF('Daily tracking'!$C$2:$C$2001,$A16)) | D16: =IF($A16="","",SUMIF('Daily tracking'!$C$2:$C$2001,$A16,'Daily tracking'!$G$2:$G$2001)) | E16: =IF($A16="","",SUMIFS('Daily tracking'!$G$2:$G$2001,'Daily tracking'!$C$2:$C$2001,$A16,'Daily tracking'!$A$2:$A$2001,">="&EOMONTH(TODAY(),-1)+1,'Daily tracking'!$A$2:$A$2001,"<="&EOMONTH(TODAY(),0))) | F16: =IF(OR($A16="",$B16=0),"",$D16/$B16) | H16: =IF($A16="","",$E16*IF($G16="",0,$G16)) | I16: =IF($A16="","",IF($B16="",0,$B16)+$H16)
C17: =IF($A17="","",COUNTIF('Daily tracking'!$C$2:$C$2001,$A17)) | D17: =IF($A17="","",SUMIF('Daily tracking'!$C$2:$C$2001,$A17,'Daily tracking'!$G$2:$G$2001)) | E17: =IF($A17="","",SUMIFS('Daily tracking'!$G$2:$G$2001,'Daily tracking'!$C$2:$C$2001,$A17,'Daily tracking'!$A$2:$A$2001,">="&EOMONTH(TODAY(),-1)+1,'Daily tracking'!$A$2:$A$2001,"<="&EOMONTH(TODAY(),0))) | F17: =IF(OR($A17="",$B17=0),"",$D17/$B17) | H17: =IF($A17="","",$E17*IF($G17="",0,$G17)) | I17: =IF($A17="","",IF($B17="",0,$B17)+$H17)
... C21: =IF($A21="","",COUNTIF('Daily tracking'!$C$2:$C$2001,$A21)) | D21: =IF($A21="","",SUMIF('Daily tracking'!$C$2:$C$2001,$A21,'Daily tracking'!$G$2:$G$2001)) | E21: =IF($A21="","",SUMIFS('Daily tracking'!$G$2:$G$2001,'Daily tracking'!$C$2:$C$2001,$A21,'Daily tracking'!$A$2:$A$2001,">="&EOMONTH(TODAY(),-1)+1,'Daily tracking'!$A$2:$A$2001,"<="&EOMONTH(TODAY(),0))) | F21: =IF(OR($A21="",$B21=0),"",$D21/$B21) | H21: =IF($A21="","",$E21*IF($G21="",0,$G21)) | I21: =IF($A21="","",IF($B21="",0,$B21)+$H21)

Sheet Expenses
A1: Date | B1: Category | C1: Amount | D1: Note | F1: Salaries pull from the Employee sheet; product buys go on the Purchases sheet. Don't log either here.

Sheet Purchases
A1: Date | B1: Product | C1: Qty | D1: Unit Cost | E1: Total Cost | F1: Supplier | G1: Note
E2: =IF($B2="","",$C2*$D2)
E3: =IF($B3="","",$C3*$D3)
E4: =IF($B4="","",$C4*$D4)
E5: =IF($B5="","",$C5*$D5)
E6: =IF($B6="","",$C6*$D6)
E7: =IF($B7="","",$C7*$D7)
E8: =IF($B8="","",$C8*$D8)
E9: =IF($B9="","",$C9*$D9)
E10: =IF($B10="","",$C10*$D10)
E11: =IF($B11="","",$C11*$D11)
E12: =IF($B12="","",$C12*$D12)
E13: =IF($B13="","",$C13*$D13)
... E1001: =IF($B1001="","",$C1001*$D1001)

Sheet Inventory
A1: Product | B1: Type | C1: Unit | D1: Opening Stock | E1: Opening Unit Cost | F1: Purchased | G1: Used / Wastage | H1: In Stock | I1: Reorder Level | J1: Status | K1: Avg Unit Cost | L1: Stock Value
F2: =IF($A2="","",SUMIF(Purchases!$B$2:$B$1001,$A2,Purchases!$C$2:$C$1001)) | H2: =IF($A2="","",IF($D2="",0,$D2)+$F2-IF($G2="",0,$G2)) | J2: =IF($A2="","",IF($I2="","OK",IF($H2<=$I2,"REORDER","OK"))) | K2: =IF($A2="","",IFERROR((IF($D2="",0,$D2)*IF($E2="",0,$E2)+SUMIF(Purchases!$B$2:$B$1001,$A2,Purchases!$E$2:$E$1001))/(IF($D2="",0,$D2)+SUMIF(Purchases!$B$2:$B$1001,$A2,Purchases!$C$2:$C$1001)),0)) | L2: =IF($A2="","",$H2*$K2)
F3: =IF($A3="","",SUMIF(Purchases!$B$2:$B$1001,$A3,Purchases!$C$2:$C$1001)) | H3: =IF($A3="","",IF($D3="",0,$D3)+$F3-IF($G3="",0,$G3)) | J3: =IF($A3="","",IF($I3="","OK",IF($H3<=$I3,"REORDER","OK"))) | K3: =IF($A3="","",IFERROR((IF($D3="",0,$D3)*IF($E3="",0,$E3)+SUMIF(Purchases!$B$2:$B$1001,$A3,Purchases!$E$2:$E$1001))/(IF($D3="",0,$D3)+SUMIF(Purchases!$B$2:$B$1001,$A3,Purchases!$C$2:$C$1001)),0)) | L3: =IF($A3="","",$H3*$K3)
F4: =IF($A4="","",SUMIF(Purchases!$B$2:$B$1001,$A4,Purchases!$C$2:$C$1001)) | H4: =IF($A4="","",IF($D4="",0,$D4)+$F4-IF($G4="",0,$G4)) | J4: =IF($A4="","",IF($I4="","OK",IF($H4<=$I4,"REORDER","OK"))) | K4: =IF($A4="","",IFERROR((IF($D4="",0,$D4)*IF($E4="",0,$E4)+SUMIF(Purchases!$B$2:$B$1001,$A4,Purchases!$E$2:$E$1001))/(IF($D4="",0,$D4)+SUMIF(Purchases!$B$2:$B$1001,$A4,Purchases!$C$2:$C$1001)),0)) | L4: =IF($A4="","",$H4*$K4)
F5: =IF($A5="","",SUMIF(Purchases!$B$2:$B$1001,$A5,Purchases!$C$2:$C$1001)) | H5: =IF($A5="","",IF($D5="",0,$D5)+$F5-IF($G5="",0,$G5)) | J5: =IF($A5="","",IF($I5="","OK",IF($H5<=$I5,"REORDER","OK"))) | K5: =IF($A5="","",IFERROR((IF($D5="",0,$D5)*IF($E5="",0,$E5)+SUMIF(Purchases!$B$2:$B$1001,$A5,Purchases!$E$2:$E$1001))/(IF($D5="",0,$D5)+SUMIF(Purchases!$B$2:$B$1001,$A5,Purchases!$C$2:$C$1001)),0)) | L5: =IF($A5="","",$H5*$K5)
F6: =IF($A6="","",SUMIF(Purchases!$B$2:$B$1001,$A6,Purchases!$C$2:$C$1001)) | H6: =IF($A6="","",IF($D6="",0,$D6)+$F6-IF($G6="",0,$G6)) | J6: =IF($A6="","",IF($I6="","OK",IF($H6<=$I6,"REORDER","OK"))) | K6: =IF($A6="","",IFERROR((IF($D6="",0,$D6)*IF($E6="",0,$E6)+SUMIF(Purchases!$B$2:$B$1001,$A6,Purchases!$E$2:$E$1001))/(IF($D6="",0,$D6)+SUMIF(Purchases!$B$2:$B$1001,$A6,Purchases!$C$2:$C$1001)),0)) | L6: =IF($A6="","",$H6*$K6)
F7: =IF($A7="","",SUMIF(Purchases!$B$2:$B$1001,$A7,Purchases!$C$2:$C$1001)) | H7: =IF($A7="","",IF($D7="",0,$D7)+$F7-IF($G7="",0,$G7)) | J7: =IF($A7="","",IF($I7="","OK",IF($H7<=$I7,"REORDER","OK"))) | K7: =IF($A7="","",IFERROR((IF($D7="",0,$D7)*IF($E7="",0,$E7)+SUMIF(Purchases!$B$2:$B$1001,$A7,Purchases!$E$2:$E$1001))/(IF($D7="",0,$D7)+SUMIF(Purchases!$B$2:$B$1001,$A7,Purchases!$C$2:$C$1001)),0)) | L7: =IF($A7="","",$H7*$K7)
F8: =IF($A8="","",SUMIF(Purchases!$B$2:$B$1001,$A8,Purchases!$C$2:$C$1001)) | H8: =IF($A8="","",IF($D8="",0,$D8)+$F8-IF($G8="",0,$G8)) | J8: =IF($A8="","",IF($I8="","OK",IF($H8<=$I8,"REORDER","OK"))) | K8: =IF($A8="","",IFERROR((IF($D8="",0,$D8)*IF($E8="",0,$E8)+SUMIF(Purchases!$B$2:$B$1001,$A8,Purchases!$E$2:$E$1001))/(IF($D8="",0,$D8)+SUMIF(Purchases!$B$2:$B$1001,$A8,Purchases!$C$2:$C$1001)),0)) | L8: =IF($A8="","",$H8*$K8)
F9: =IF($A9="","",SUMIF(Purchases!$B$2:$B$1001,$A9,Purchases!$C$2:$C$1001)) | H9: =IF($A9="","",IF($D9="",0,$D9)+$F9-IF($G9="",0,$G9)) | J9: =IF($A9="","",IF($I9="","OK",IF($H9<=$I9,"REORDER","OK"))) | K9: =IF($A9="","",IFERROR((IF($D9="",0,$D9)*IF($E9="",0,$E9)+SUMIF(Purchases!$B$2:$B$1001,$A9,Purchases!$E$2:$E$1001))/(IF($D9="",0,$D9)+SUMIF(Purchases!$B$2:$B$1001,$A9,Purchases!$C$2:$C$1001)),0)) | L9: =IF($A9="","",$H9*$K9)
F10: =IF($A10="","",SUMIF(Purchases!$B$2:$B$1001,$A10,Purchases!$C$2:$C$1001)) | H10: =IF($A10="","",IF($D10="",0,$D10)+$F10-IF($G10="",0,$G10)) | J10: =IF($A10="","",IF($I10="","OK",IF($H10<=$I10,"REORDER","OK"))) | K10: =IF($A10="","",IFERROR((IF($D10="",0,$D10)*IF($E10="",0,$E10)+SUMIF(Purchases!$B$2:$B$1001,$A10,Purchases!$E$2:$E$1001))/(IF($D10="",0,$D10)+SUMIF(Purchases!$B$2:$B$1001,$A10,Purchases!$C$2:$C$1001)),0)) | L10: =IF($A10="","",$H10*$K10)
F11: =IF($A11="","",SUMIF(Purchases!$B$2:$B$1001,$A11,Purchases!$C$2:$C$1001)) | H11: =IF($A11="","",IF($D11="",0,$D11)+$F11-IF($G11="",0,$G11)) | J11: =IF($A11="","",IF($I11="","OK",IF($H11<=$I11,"REORDER","OK"))) | K11: =IF($A11="","",IFERROR((IF($D11="",0,$D11)*IF($E11="",0,$E11)+SUMIF(Purchases!$B$2:$B$1001,$A11,Purchases!$E$2:$E$1001))/(IF($D11="",0,$D11)+SUMIF(Purchases!$B$2:$B$1001,$A11,Purchases!$C$2:$C$1001)),0)) | L11: =IF($A11="","",$H11*$K11)
F12: =IF($A12="","",SUMIF(Purchases!$B$2:$B$1001,$A12,Purchases!$C$2:$C$1001)) | H12: =IF($A12="","",IF($D12="",0,$D12)+$F12-IF($G12="",0,$G12)) | J12: =IF($A12="","",IF($I12="","OK",IF($H12<=$I12,"REORDER","OK"))) | K12: =IF($A12="","",IFERROR((IF($D12="",0,$D12)*IF($E12="",0,$E12)+SUMIF(Purchases!$B$2:$B$1001,$A12,Purchases!$E$2:$E$1001))/(IF($D12="",0,$D12)+SUMIF(Purchases!$B$2:$B$1001,$A12,Purchases!$C$2:$C$1001)),0)) | L12: =IF($A12="","",$H12*$K12)
F13: =IF($A13="","",SUMIF(Purchases!$B$2:$B$1001,$A13,Purchases!$C$2:$C$1001)) | H13: =IF($A13="","",IF($D13="",0,$D13)+$F13-IF($G13="",0,$G13)) | J13: =IF($A13="","",IF($I13="","OK",IF($H13<=$I13,"REORDER","OK"))) | K13: =IF($A13="","",IFERROR((IF($D13="",0,$D13)*IF($E13="",0,$E13)+SUMIF(Purchases!$B$2:$B$1001,$A13,Purchases!$E$2:$E$1001))/(IF($D13="",0,$D13)+SUMIF(Purchases!$B$2:$B$1001,$A13,Purchases!$C$2:$C$1001)),0)) | L13: =IF($A13="","",$H13*$K13)
... F201: =IF($A201="","",SUMIF(Purchases!$B$2:$B$1001,$A201,Purchases!$C$2:$C$1001)) | H201: =IF($A201="","",IF($D201="",0,$D201)+$F201-IF($G201="",0,$G201)) | J201: =IF($A201="","",IF($I201="","OK",IF($H201<=$I201,"REORDER","OK"))) | K201: =IF($A201="","",IFERROR((IF($D201="",0,$D201)*IF($E201="",0,$E201)+SUMIF(Purchases!$B$2:$B$1001,$A201,Purchases!$E$2:$E$1001))/(IF($D201="",0,$D201)+SUMIF(Purchases!$B$2:$B$1001,$A201,Purchases!$C$2:$C$1001)),0)) | L201: =IF($A201="","",$H201*$K201)

Sheet Retention
A1: CUSTOMER RETENTION
A3: THE NUMBERS | F3: WHERE CUSTOMERS COME FROM
A4: Total customers | B4: =COUNTIF('Customer Database'!$C$2:$C$501,">0") -> 0 | F4: Source | G4: Customers | H4: Total Spend | I4: Avg Spend
A5: New customers (this month) | B5: =COUNTIFS('Customer Database'!$Q$2:$Q$501,">="&EOMONTH(TODAY(),-1)+1,'Customer Database'!$Q$2:$Q$501,"<="&EOMONTH(TODAY(),0)) -> 0 | F5: Walk-in | G5: =COUNTIF('Customer Database'!$M$2:$M$501,F5) -> 0 | H5: =SUMIF('Customer Database'!$M$2:$M$501,F5,'Customer Database'!$D$2:$D$501) -> 0 | I5: =IFERROR(SUMIF('Customer Database'!$M$2:$M$501,F5,'Customer Database'!$D$2:$D$501)/COUNTIF('Customer Database'!$M$2:$M$501,F5),0) -> 0
